<robot name="little_bot">
    <link name="base_link">
        <inertial>
            <origin xyz="0.002379389645183935 1.5870941312697752e-17 0.014613632958144862" rpy="0.0 0.0 0.0" />
            <mass value="1.214879905211409" />
            <inertia ixx="0.004193891160988535" iyy="0.00417277261462651" izz="0.008141070670075393" ixy="-1.4283119134593308e-15" iyz="-4.894818460227988e-19" ixz="-6.374008005996398e-05" />
        </inertial>
        <visual name="base_link_visual">
            <origin xyz="0.0 0.0 0.0" rpy="0.0 0.0 0.0" />
            <geometry>
                <mesh filename="package://littlebot/meshes/base_link.stl" scale="0.001 0.001 0.001" />
            </geometry>
        </visual>
        <collision name="base_link_collision">
            <origin xyz="0.0 0.0 0.0" rpy="0.0 0.0 0.0" />
            <geometry>
                <mesh filename="package://littlebot/meshes/base_link.stl" scale="0.001 0.001 0.001" />
            </geometry>
        </collision>
    </link>
    <link name="lidar">
        <inertial>
            <origin xyz="0.0 4.615770966296263e-18 0.0040000000000000036" rpy="0.0 -0.0 0.0" />
            <mass value="0.032634864485490744" />
            <inertia ixx="1.0168479859270376e-05" iyy="1.0168479859270986e-05" izz="1.9988854497362814e-05" ixy="-3.7658764995285325e-21" iyz="4.368416739453094e-21" ixz="-2.710505431213761e-20" />
        </inertial>
        <visual name="lidar_visual">
            <origin xyz="-0.055 0.0 -0.045" rpy="0.0 -0.0 0.0" />
            <geometry>
                <mesh filename="package://littlebot/meshes/lidar.stl" scale="0.001 0.001 0.001" />
            </geometry>
        </visual>
        <collision name="lidar_collision">
            <origin xyz="-0.055 0.0 -0.045" rpy="0.0 -0.0 0.0" />
            <geometry>
                <mesh filename="package://littlebot/meshes/lidar.stl" scale="0.001 0.001 0.001" />
            </geometry>
        </collision>
    </link>
    <link name="imu">
        <inertial>
            <origin xyz="0.0 0.0 0.0010000000000000002" rpy="0.0 -0.0 0.0" />
            <mass value="0.0012720000000000001" />
            <inertia ixx="4.2823999999999994e-08" iyy="9.582400000000004e-08" izz="1.3780000000000003e-07" ixy="0.0" iyz="2.9420910152566647e-24" ixz="0.0" />
        </inertial>
        <visual name="imu_visual">
            <origin xyz="0.0 0.0 0.0" rpy="3.141592653589793 -0.0 0.0" />
            <geometry>
                <mesh filename="package://littlebot/meshes/imu.stl" scale="0.001 0.001 0.001" />
            </geometry>
        </visual>
        <collision name="imu_collision">
            <origin xyz="0.0 0.0 0.0" rpy="3.141592653589793 -0.0 0.0" />
            <geometry>
                <mesh filename="package://littlebot/meshes/imu.stl" scale="0.001 0.001 0.001" />
            </geometry>
        </collision>
    </link>
    <link name="front_right_wheel-v1_Component3">
        <inertial>
            <origin xyz="3.102295472042764e-08 -2.9861664205750158e-05 3.090283746011757e-08" rpy="0.0 0.0 0.0" />
            <mass value="0.06587225705261189" />
            <inertia ixx="1.8513650218442684e-05" iyy="2.8353314654871573e-05" izz="1.8513608276880163e-05" ixy="1.1571605017239706e-12" iyz="9.165734685437386e-13" ixz="-3.303886807260619e-11" />
        </inertial>
        <visual name="front_right_wheel-v1_Component3_visual">
            <origin xyz="0.0 0.0 0.0" rpy="0.0 0.0 0.0" />
            <geometry>
                <mesh filename="package://littlebot/meshes/front_right_wheel-v1_Component3.stl" scale="0.001 0.001 0.001" />
            </geometry>
        </visual>
        <collision name="front_right_wheel-v1_Component3_collision">
            <origin xyz="0.0 0.0 0.0" rpy="0.0 0.0 0.0" />
            <geometry>
                <mesh filename="package://littlebot/meshes/front_right_wheel-v1_Component3.stl" scale="0.001 0.001 0.001" />
            </geometry>
        </collision>
    </link>
    <link name="front_left_wheel-v1_Component3">
        <inertial>
            <origin xyz="3.1022954720830595e-08 -2.9861664205750317e-05 3.090283746010059e-08" rpy="0.0 0.0 0.0" />
            <mass value="0.06587225705261189" />
            <inertia ixx="1.8513650218442623e-05" iyy="2.8353314654872095e-05" izz="1.851360827688021e-05" ixy="1.157160581724263e-12" iyz="9.165735119670315e-13" ixz="-3.303886805523621e-11" />
        </inertial>
        <visual name="front_left_wheel-v1_Component3_visual">
            <origin xyz="0.0 0.0 0.0" rpy="0.0 0.0 0.0" />
            <geometry>
                <mesh filename="package://littlebot/meshes/front_left_wheel-v1_Component3.stl" scale="0.001 0.001 0.001" />
            </geometry>
        </visual>
        <collision name="front_left_wheel-v1_Component3_collision">
            <origin xyz="0.0 0.0 0.0" rpy="0.0 0.0 0.0" />
            <geometry>
                <mesh filename="package://littlebot/meshes/front_left_wheel-v1_Component3.stl" scale="0.001 0.001 0.001" />
            </geometry>
        </collision>
    </link>
    <link name="rear_right_wheel-v1_Component3">
        <inertial>
            <origin xyz="3.102295472075925e-08 -2.986166420575028e-05 3.090283746010665e-08" rpy="0.0 0.0 0.0" />
            <mass value="0.06587225705261189" />
            <inertia ixx="1.8513650218442975e-05" iyy="2.835331465487208e-05" izz="1.851360827688055e-05" ixy="1.1571605039851175e-12" iyz="9.165735332462261e-13" ixz="-3.303886806734116e-11" />
        </inertial>
        <visual name="rear_right_wheel-v1_Component3_visual">
            <origin xyz="0.0 0.0 0.0" rpy="0.0 0.0 0.0" />
            <geometry>
                <mesh filename="package://littlebot/meshes/rear_right_wheel-v1_Component3.stl" scale="0.001 0.001 0.001" />
            </geometry>
        </visual>
        <collision name="rear_right_wheel-v1_Component3_collision">
            <origin xyz="0.0 0.0 0.0" rpy="0.0 0.0 0.0" />
            <geometry>
                <mesh filename="package://littlebot/meshes/rear_right_wheel-v1_Component3.stl" scale="0.001 0.001 0.001" />
            </geometry>
        </collision>
    </link>
    <link name="rear_left_wheel-v1_Component3">
        <inertial>
            <origin xyz="3.102295472096322e-08 -2.986166420575033e-05 3.090283746010059e-08" rpy="0.0 0.0 0.0" />
            <mass value="0.06587225705261189" />
            <inertia ixx="1.8513650218442636e-05" iyy="2.8353314654872176e-05" izz="1.8513608276880427e-05" ixy="1.1571606464475934e-12" iyz="9.165735119668851e-13" ixz="-3.303886807556501e-11" />
        </inertial>
        <visual name="rear_left_wheel-v1_Component3_visual">
            <origin xyz="0.0 0.0 0.0" rpy="0.0 0.0 0.0" />
            <geometry>
                <mesh filename="package://littlebot/meshes/rear_left_wheel-v1_Component3.stl" scale="0.001 0.001 0.001" />
            </geometry>
        </visual>
        <collision name="rear_left_wheel-v1_Component3_collision">
            <origin xyz="0.0 0.0 0.0" rpy="0.0 0.0 0.0" />
            <geometry>
                <mesh filename="package://littlebot/meshes/rear_left_wheel-v1_Component3.stl" scale="0.001 0.001 0.001" />
            </geometry>
        </collision>
    </link>
    <link name="z_rail_link-v5">
        <inertial>
            <origin xyz="0.02474874000000181 0.024748739999999922 0.05107759896613722" rpy="0.0 -0.0 0.0" />
            <mass value="0.31575562187676676" />
            <inertia ixx="0.000570845664483316" iyy="0.0005708456644839786" izz="0.00011138220861199317" ixy="4.264173667979578e-18" iyz="-7.052806199089826e-19" ixz="2.7538735181131813e-17" />
        </inertial>
        <visual name="z_rail_link-v5_visual">
            <origin xyz="0.02474873999999984 0.02474873999999992 -0.0025000000000000356" rpy="-5.449290170266184e-16 3.830269434956793e-15 -3.944304526105099e-31" />
            <geometry>
                <mesh filename="package://littlebot/meshes/z_rail_link-v5.stl" scale="0.001 0.001 0.001" />
            </geometry>
        </visual>
        <collision name="z_rail_link-v5_collision">
            <origin xyz="0.02474873999999984 0.02474873999999992 -0.0025000000000000356" rpy="-5.449290170266184e-16 3.830269434956793e-15 -3.944304526105099e-31" />
            <geometry>
                <mesh filename="package://littlebot/meshes/z_rail_link-v5.stl" scale="0.001 0.001 0.001" />
            </geometry>
        </collision>
    </link>
    <link name="z_slider_link-v5">
        <inertial>
            <origin xyz="0.07466764525346652 1.34378117301319e-09 0.10500000220511052" rpy="0.0 -0.0 0.0" />
            <mass value="0.031761577565023694" />
            <inertia ixx="2.559867967399628e-06" iyy="8.028355646136636e-05" izz="8.167462322133503e-05" ixy="-3.942596894986924e-12" iyz="-1.0588322302656455e-13" ixz="-2.5252239535533683e-12" />
        </inertial>
        <visual name="z_slider_link-v5_visual">
            <origin xyz="2.9309887850104134e-16 -1.0213239453072002e-16 0.11500000000000053" rpy="3.1415926535897927 3.4360595006111733e-15 -2.8253475240680457e-15" />
            <geometry>
                <mesh filename="package://littlebot/meshes/z_slider_link-v5.stl" scale="0.001 0.001 0.001" />
            </geometry>
        </visual>
        <collision name="z_slider_link-v5_collision">
            <origin xyz="2.9309887850104134e-16 -1.0213239453072002e-16 0.11500000000000053" rpy="3.1415926535897927 3.4360595006111733e-15 -2.8253475240680457e-15" />
            <geometry>
                <mesh filename="package://littlebot/meshes/z_slider_link-v5.stl" scale="0.001 0.001 0.001" />
            </geometry>
        </collision>
    </link>
    <link name="camera-v1">
        <inertial>
            <origin xyz="2.3980817331903383e-16 -8.88178419700126e-17 0.007499999999999289" rpy="0.0 -0.0 0.0" />
            <mass value="0.044156249999999994" />
            <inertia ixx="3.1277343749997345e-06" iyy="1.6558593749994768e-06" izz="3.127734375000019e-06" ixy="-4.7330910824196473e-35" iyz="-9.660491564065596e-35" ixz="5.421010862427522e-20" />
        </inertial>
        <visual name="camera-v1_visual">
            <origin xyz="0.00025000000000023446 -8.881784197001253e-17 -7.105427357601002e-16" rpy="1.1339040066817218e-29 1.734723475976807e-16 -3.944304526105511e-31" />
            <geometry>
                <mesh filename="package://littlebot/meshes/camera-v1.stl" scale="0.001 0.001 0.001" />
            </geometry>
        </visual>
        <collision name="camera-v1_collision">
            <origin xyz="0.00025000000000023446 -8.881784197001253e-17 -7.105427357601002e-16" rpy="1.1339040066817218e-29 1.734723475976807e-16 -3.944304526105511e-31" />
            <geometry>
                <mesh filename="package://littlebot/meshes/camera-v1.stl" scale="0.001 0.001 0.001" />
            </geometry>
        </collision>
    </link>
    <link name="arm_link-v1">
        <inertial>
            <origin xyz="0.05903895344928337 -2.7403028178625278e-05 -0.014749999999999486" rpy="0.0 -0.0 0.0" />
            <mass value="0.03346092824173876" />
            <inertia ixx="1.9782354348874334e-06" iyy="5.279703273267718e-05" izz="5.1890800486396535e-05" ixy="5.5152226988283357e-08" iyz="-4.235164736271502e-22" ixz="7.457913342337301e-18" />
        </inertial>
        <visual name="arm_link-v1_visual">
            <origin xyz="0.0525000000000006 -0.007250000149011911 -0.014749999999999482" rpy="-1.570796326794897 -1.5777218104420236e-30 -3.436059500611175e-15" />
            <geometry>
                <mesh filename="package://littlebot/meshes/arm_link-v1.stl" scale="0.001 0.001 0.001" />
            </geometry>
        </visual>
        <collision name="arm_link-v1_collision">
            <origin xyz="0.0525000000000006 -0.007250000149011911 -0.014749999999999482" rpy="-1.570796326794897 -1.5777218104420236e-30 -3.436059500611175e-15" />
            <geometry>
                <mesh filename="package://littlebot/meshes/arm_link-v1.stl" scale="0.001 0.001 0.001" />
            </geometry>
        </collision>
    </link>
    <joint name="base_link_lidar_joint" type="fixed">
        <origin xyz="0.055 0.0 0.045" rpy="0.0 -0.0 0.0" />
        <parent link="base_link" />
        <child link="lidar" />
    </joint>
    <joint name="base_link_imu_joint" type="fixed">
        <origin xyz="0.0 0.0 0.0" rpy="3.141592653589793 -0.0 0.0" />
        <parent link="base_link" />
        <child link="imu" />
    </joint>
    <joint name="base_link_front_right_wheel_joint" type="fixed">
        <origin xyz="0.07 -0.128 0.0125" rpy="0 0 0" />
        <parent link="base_link" />
        <child link="front_right_wheel-v1_Component3" />
        <!--<axis xyz="0 1 0" />-->
    </joint>
    <joint name="base_link_front_left_wheel_joint" type="fixed">
        <origin xyz="0.07 0.128 0.0125" rpy="0 0 0" />
        <parent link="base_link" />
        <child link="front_left_wheel-v1_Component3" />
        <!--<axis xyz="0 1 0" />-->
    </joint>
    <joint name="base_link_rear_right_wheel_joint" type="fixed">
        <origin xyz="-0.07 -0.128 0.0125" rpy="0 0 0" />
        <parent link="base_link" />
        <child link="rear_right_wheel-v1_Component3" />
        <!--<axis xyz="0 1 0" />-->
    </joint>
    <joint name="base_link_rear_left_wheel_joint" type="fixed">
        <origin xyz="-0.07 0.128 0.0125" rpy="0 0 0" />
        <parent link="base_link" />
        <child link="rear_left_wheel-v1_Component3" />
        <!--<axis xyz="0 1 0" />-->
    </joint>
    <joint name="base_link_pillar_fixed_joint" type="fixed">
        <origin xyz="-0.06724874 -0.024748739999999998 0.07" rpy="0.0 -0.0 0.0" />
        <parent link="base_link" />
        <child link="z_rail_link-v5" />
    </joint>
    <joint name="z_rail_link-v5_z_axis_joint" type="prismatic">
        <origin xyz="0.024748739999999998 0.024748739999999998 0.005" rpy="-9.860761315262648e-32 -0.0 -5.153823899991262e-47" />
        <parent link="z_rail_link-v5" />
        <child link="z_slider_link-v5" />
        <axis xyz="0.0 -9.860761315262648e-32 1.0" />
        <limit lower="0.0" upper="0.095" effort="1000000" velocity="1000000" />
        <dynamics damping="1.0" friction="1.0"/>
    </joint>
    <joint name="z_rail_link-v5_camera_joint" type="fixed">
        <origin xyz="0.024748739999999998 0.024748739999999998 0.125" rpy="-9.860761315262648e-32 -0.0 -5.153823899991262e-47" />
        <parent link="z_rail_link-v5" />
        <child link="camera-v1" />
    </joint>
    <joint name="z_slider_link-v5_arm_joint" type="continuous">
        <origin xyz="0.153 -0.015 0.105" rpy="1.5707963267948966 0.0 0.0" /> 
        <parent link="z_slider_link-v5" />
        <child link="arm_link-v1" />
        <axis xyz="0.0 0.0 -1.0" /> <dynamics damping="1.0" friction="1.0"/>
    </joint>
    <!--gazebo plugin-->
    <gazebo>
        <plugin name="omni_controller" filename="libgazebo_ros_planar_move.so">
            <ros>
                <namespace>/</namespace>
                <remapping>cmd_vel:=cmd_vel</remapping>
                <remapping>odom:=odom</remapping>
            </ros>
            <update_rate>100</update_rate>
            <publish_rate>50</publish_rate>
            <publish_odom>true</publish_odom>
            <publish_odom_tf>true</publish_odom_tf>
            <odometry_frame>odom</odometry_frame>
            <robot_base_frame>base_link</robot_base_frame>
            <covariance_x>0.0001</covariance_x>
            <covariance_y>0.0001</covariance_y>
            <covariance_yaw>0.01</covariance_yaw>
        </plugin>
    </gazebo>
    <gazebo reference="lidar">
        <sensor name="lidar_sensor" type="ray">
            <always_on>true</always_on>
            <visualize>true</visualize>
            <update_rate>10</update_rate>
            <ray>
                <scan>
                    <horizontal>
                        <samples>360</samples>
                        <resolution>1.000000</resolution>
                        <min_angle>0.000000</min_angle>
                        <max_angle>6.28319</max_angle>
                    </horizontal>
                </scan>
                <range>
                    <min>0.120000</min>
                    <max>8.0</max>
                    <resolution>0.015000</resolution>
                </range>
            </ray>
            <plugin name="scan" filename="libgazebo_ros_ray_sensor.so">
                <ros>
                    <remapping>~/out:=scan</remapping>
                </ros>
                <output_type>sensor_msgs/LaserScan</output_type>
                <frame_name>lidar</frame_name>
            </plugin>
        </sensor>
    </gazebo>
    <gazebo reference="imu">
        <sensor name="imu_sensor" type="imu">
            <always_on>true</always_on>
            <update_rate>100</update_rate>
            <visualize>true</visualize>
            <plugin filename="libgazebo_ros_imu_sensor.so" name="imu_plugin">
                <ros>
                    <remapping>~/out:=imu</remapping>
                </ros>
                <initial_orientation_as_reference>false</initial_orientation_as_reference>
            </plugin>
        </sensor>
    </gazebo>
    <gazebo reference="camera-v1">
        <sensor type="camera" name="camera_sensor">
            <update_rate>30.0</update_rate>
            <visualize>true</visualize>
            <camera name="head">
                <horizontal_fov>1.3962634</horizontal_fov>
                <image>
                    <width>640</width>
                    <height>480</height>
                    <format>R8G8B8</format>
                </image>
                <clip>
                    <near>0.02</near>
                    <far>300</far>
                </clip>
            </camera>
            <plugin name="camera_controller" filename="libgazebo_ros_camera.so">
                <alwaysOn>true</alwaysOn>
                <updateRate>0.0</updateRate>
                <cameraName>littlebot/camera</cameraName>
                <imageTopicName>image_raw</imageTopicName>
                <cameraInfoTopicName>camera_info</cameraInfoTopicName>
                <frameName>camera-v1</frameName>
            </plugin>
        </sensor>
    </gazebo>
    <gazebo>
        <plugin name="my_joint_state_publisher" filename="libgazebo_ros_joint_state_publisher.so">
            <ros>
                <remapping>~/out:=joint_states</remapping>
            </ros>
            <update_rate>30</update_rate>
            <joint_name>z_rail_link-v5_z_axis_joint</joint_name>
            <joint_name>z_slider_link-v5_arm_joint</joint_name>
        </plugin>
    </gazebo>
    <gazebo>
        <plugin name="my_arm_controller" filename="libgazebo_ros_joint_pose_trajectory.so">
            <update_rate>30</update_rate>
            <joint_name>z_rail_link-v5_z_axis_joint</joint_name>
            <joint_name>z_slider_link-v5_arm_joint</joint_name>
            <topic_name>/set_joint_trajectory</topic_name>
            <reference_link>base_link</reference_link>
        </plugin>
    </gazebo>
</robot>